<?xml version="1.0" ?>
<!-- =================================================================================== -->
<!-- |    This document was autogenerated by xacro from /home/gregorio/franka_description/robots/fr3/fr3.urdf.xacro | -->
<!-- |    EDITING THIS FILE BY HAND IS NOT RECOMMENDED                                 | -->
<!-- =================================================================================== -->
<robot name="panda_with_adapt_hand">
  <!-- safety_distance: Minimum safety distance in [m] by which the collision volumes are expanded and which is enforced during robot motions -->
  <!-- arm_id: Namespace of the robot arm. Serves to differentiate between arms in case of multiple instances. -->
  <!-- joint_limits: description of the joint limits that comes from a YAML file. Example definition: ${xacro.load_yaml('$(find franka_description)/robots/fr3/joint_limits.yaml')} -->
  <!-- kinematics: description of the kinematics that comes from a YAML file. Example definition: ${xacro.load_yaml('$(find franka_description)/robots/fr3/kinematics.yaml')} -->
  <!-- inertials: description of the inertials that comes from a YAML file. Example definition: ${xacro.load_yaml('$(find franka_description)/robots/fr3/inertials.yaml')} -->
  <!-- dynamics: description of the dynamics that comes from a YAML file. Example definition: ${xacro.load_yaml('$(find franka_description)/robots/fr3/dynamics.yaml')} -->
  <link name="base">
      </link>
  <joint name="fr3_base_joint" type="fixed">
    <parent link="base"/>
    <child link="fr3_link0"/>
    <origin rpy="0 0 0" xyz="0 0 0"/>
  </joint>
  <!-- sub-link defining detailed meshes for collision with environment -->
  <link name="fr3_link0">
    <visual name="fr3_link0_visual">
      <geometry>
        <mesh filename="/home/vigno/github/VMRobotControl.jl/URDFs/franka_hand_description/meshes/robot_arms/fr3/visual/link0.dae"/>
      </geometry>
    </visual>
    <collision name="fr3_link0_collision">
      <geometry>
        <mesh filename="/home/vigno/github/VMRobotControl.jl/URDFs/franka_hand_description/meshes/robot_arms/fr3/collision/link0.stl"/>
      </geometry>
    </collision>
    <inertial>
      <origin rpy="0 0 0" xyz="-0.0172 0.0004 0.0745"/>
      <mass value="2.3966"/>
      <inertia ixx="0.009" ixy="0.0" ixz="0.002" iyy="0.0115" iyz="0.0" izz="0.0085"/>
    </inertial>
  </link>
  <!-- sub-link defining detailed meshes for collision with environment -->
  <link name="fr3_link1">
    <visual name="fr3_link1_visual">
      <geometry>
        <mesh filename="/home/vigno/github/VMRobotControl.jl/URDFs/franka_hand_description/meshes/robot_arms/fr3/visual/link1.dae"/>
      </geometry>
    </visual>
    <collision name="fr3_link1_collision">
      <geometry>
        <mesh filename="/home/vigno/github/VMRobotControl.jl/URDFs/franka_hand_description/meshes/robot_arms/fr3/collision/link1.stl"/>
      </geometry>
    </collision>
    <inertial>
      <origin rpy="0 0 0" xyz="0.0000004128 -0.0181251324 -0.0386035970"/>
      <mass value="2.9274653454"/>
      <inertia ixx="0.023927316485107913" ixy="1.3317903455714081e-05" ixz="-0.00011404774918616684" iyy="0.0224821613275756" iyz="-0.0019950320628240115" izz="0.006350098258530016"/>
    </inertial>
  </link>
  <joint name="fr3_joint1" type="revolute">
    <origin rpy="0 0 0" xyz="0 0 0.333"/>
    <parent link="fr3_link0"/>
    <child link="fr3_link1"/>
    <axis xyz="0 0 1"/>
    <limit effort="87.0" lower="-2.7437" upper="2.7437" velocity="2.62"/>

  </joint>
  <!-- sub-link defining detailed meshes for collision with environment -->
  <link name="fr3_link2">
    <visual name="fr3_link2_visual">
      <geometry>
        <mesh filename="/home/vigno/github/VMRobotControl.jl/URDFs/franka_hand_description/meshes/robot_arms/fr3/visual/link2.dae"/>
      </geometry>
    </visual>
    <collision name="fr3_link2_collision">
      <geometry>
        <mesh filename="/home/vigno/github/VMRobotControl.jl/URDFs/franka_hand_description/meshes/robot_arms/fr3/collision/link2.stl"/>
      </geometry>
    </collision>
    <inertial>
      <origin rpy="0 0 0" xyz="0.0031828864 -0.0743221644 0.0088146084"/>
      <mass value="2.9355370338"/>
      <inertia ixx="0.041938946257609425" ixy="0.00020257331521090626" ixz="0.004077784227179924" iyy="0.02514514885014724" iyz="-0.0042252158006570156" izz="0.06170214472888839"/>
    </inertial>
  </link>
  <joint name="fr3_joint2" type="revolute">
    <origin rpy="-1.570796326794897 0 0" xyz="0 0 0"/>
    <parent link="fr3_link1"/>
    <child link="fr3_link2"/>
    <axis xyz="0 0 1"/>
    <limit effort="87.0" lower="-1.7837" upper="1.7837" velocity="2.62"/>

  </joint>
  <!-- sub-link defining detailed meshes for collision with environment -->
  <link name="fr3_link3">
    <visual name="fr3_link3_visual">
      <geometry>
        <mesh filename="/home/vigno/github/VMRobotControl.jl/URDFs/franka_hand_description/meshes/robot_arms/fr3/visual/link3.dae"/>
      </geometry>
    </visual>
    <collision name="fr3_link3_collision">
      <geometry>
        <mesh filename="/home/vigno/github/VMRobotControl.jl/URDFs/franka_hand_description/meshes/robot_arms/fr3/collision/link3.stl"/>
      </geometry>
    </collision>
    <inertial>
      <origin rpy="0 0 0" xyz="0.0407015686 -0.0048200565 -0.0289730823"/>
      <mass value="2.2449013699"/>
      <inertia ixx="0.02410142547240885" ixy="0.002404694559042109" ixz="-0.002856269270114313" iyy="0.01974053266708178" iyz="-0.002104212683891874" izz="0.019044494482244823"/>
    </inertial>
  </link>
  <joint name="fr3_joint3" type="revolute">
    <origin rpy="1.570796326794897 0 0" xyz="0 -0.316 0"/>
    <parent link="fr3_link2"/>
    <child link="fr3_link3"/>
    <axis xyz="0 0 1"/>
    <limit effort="87.0" lower="-2.9007" upper="2.9007" velocity="2.62"/>

  </joint>
  <!-- sub-link defining detailed meshes for collision with environment -->
  <link name="fr3_link4">
    <visual name="fr3_link4_visual">
      <geometry>
        <mesh filename="/home/vigno/github/VMRobotControl.jl/URDFs/franka_hand_description/meshes/robot_arms/fr3/visual/link4.dae"/>
      </geometry>
    </visual>
    <collision name="fr3_link4_collision">
      <geometry>
        <mesh filename="/home/vigno/github/VMRobotControl.jl/URDFs/franka_hand_description/meshes/robot_arms/fr3/collision/link4.stl"/>
      </geometry>
    </collision>
    <inertial>
      <origin rpy="0 0 0" xyz="-0.0459100965 0.0630492960 -0.0085187868"/>
      <mass value="2.6155955791"/>
      <inertia ixx="0.03452998321913202" ixy="0.01322552265982813" ixz="0.01015142998484113" iyy="0.028881621933049058" iyz="-0.0009762833870704552" izz="0.04125471171146641"/>
    </inertial>
  </link>
  <joint name="fr3_joint4" type="revolute">
    <origin rpy="1.570796326794897 0 0" xyz="0.0825 0 0"/>
    <parent link="fr3_link3"/>
    <child link="fr3_link4"/>
    <axis xyz="0 0 1"/>
    <limit effort="87.0" lower="-3.0421" upper="-0.1518" velocity="2.62"/>

  </joint>
  <!-- sub-link defining detailed meshes for collision with environment -->
  <link name="fr3_link5">
    <visual name="fr3_link5_visual">
      <geometry>
        <mesh filename="/home/vigno/github/VMRobotControl.jl/URDFs/franka_hand_description/meshes/robot_arms/fr3/visual/link5.dae"/>
      </geometry>
    </visual>
    <collision name="fr3_link5_collision">
      <geometry>
        <mesh filename="/home/vigno/github/VMRobotControl.jl/URDFs/franka_hand_description/meshes/robot_arms/fr3/collision/link5.stl"/>
      </geometry>
    </collision>
    <inertial>
      <origin rpy="0 0 0" xyz="-0.0016039605 0.0292536262 -0.0972965990"/>
      <mass value="2.3271207594"/>
      <inertia ixx="0.051610278463662895" ixy="-0.005715173387783472" ixz="-0.0035673167625872135" iyy="0.04787729713371481" iyz="0.010673985108535986" izz="0.016423625579357254"/>
    </inertial>
  </link>
  <joint name="fr3_joint5" type="revolute">
    <origin rpy="-1.570796326794897 0 0" xyz="-0.0825 0.384 0"/>
    <parent link="fr3_link4"/>
    <child link="fr3_link5"/>
    <axis xyz="0 0 1"/>
    <limit effort="12.0" lower="-2.8065" upper="2.8065" velocity="5.26"/>

  </joint>
  <!-- sub-link defining detailed meshes for collision with environment -->
  <link name="fr3_link6">
    <visual name="fr3_link6_visual">
      <geometry>
        <mesh filename="/home/vigno/github/VMRobotControl.jl/URDFs/franka_hand_description/meshes/robot_arms/fr3/visual/link6.dae"/>
      </geometry>
    </visual>
    <collision name="fr3_link6_collision">
      <geometry>
        <mesh filename="/home/vigno/github/VMRobotControl.jl/URDFs/franka_hand_description/meshes/robot_arms/fr3/collision/link6.stl"/>
      </geometry>
    </collision>
    <inertial>
      <origin rpy="0 0 0" xyz="0.0597131221 -0.0410294666 -0.0101692726"/>
      <mass value="1.8170376524"/>
      <inertia ixx="0.005412333594383447" ixy="0.006193456360285834" ixz="0.0014219289306117652" iyy="0.014058329545509979" iyz="-0.0013140753741120031" izz="0.016080817924212554"/>
    </inertial>
  </link>
  <joint name="fr3_joint6" type="revolute">
    <origin rpy="1.570796326794897 0 0" xyz="0 0 0"/>
    <parent link="fr3_link5"/>
    <child link="fr3_link6"/>
    <axis xyz="0 0 1"/>
    <limit effort="12.0" lower="0.5445" upper="4.5169" velocity="4.18"/>

  </joint>
  <!-- sub-link defining detailed meshes for collision with environment -->
  <link name="fr3_link7">
    <visual name="fr3_link7_visual">
      <geometry>
        <mesh filename="/home/vigno/github/VMRobotControl.jl/URDFs/franka_hand_description/meshes/robot_arms/fr3/visual/link7.dae"/>
      </geometry>
    </visual>
    <collision name="fr3_link7_collision">
      <geometry>
        <mesh filename="/home/vigno/github/VMRobotControl.jl/URDFs/franka_hand_description/meshes/robot_arms/fr3/collision/link7.stl"/>
      </geometry>
    </collision>
    <inertial>
      <origin rpy="0 0 0" xyz="0.0045225817 0.0086261921 -0.0161633251"/>
      <mass value="0.6271432862"/>
      <inertia ixx="0.00021092389150104718" ixy="-2.433299114461931e-05" ixz="4.564480393778983e-05" iyy="0.00017718568002411474" iyz="8.744070223226438e-05" izz="5.993190599659971e-05"/>
    </inertial>
  </link>
  <joint name="fr3_joint7" type="revolute">
    <origin rpy="1.570796326794897 0 0" xyz="0.088 0 0"/>
    <parent link="fr3_link6"/>
    <child link="fr3_link7"/>
    <axis xyz="0 0 1"/>
    <limit effort="12.0" lower="-3.0159" upper="3.0159" velocity="5.26"/>

  </joint>
  <link name="fr3_link8"/>
  <joint name="fr3_joint8" type="fixed">
    <origin rpy="0 0 0" xyz="0 0 0.107"/>
    <parent link="fr3_link7"/>
    <child link="fr3_link8"/>
  </joint>

  <!-- Joint connecting Panda and Adapt hand -->  
  <joint name="panda_ee_hand_base" type="fixed">
    <parent link="fr3_link8"/>
    <child link="base_link"/>
    <origin rpy="0 0 -80" xyz="0 0 0.067"/>
  </joint>

  <!-- Adapt Hand materials -->  
  <material name="hand_base">
    <color rgba="0.900 0.900 0.900 1.000"/>
  </material>
  <material name="finger_base">
    <color rgba="0.700 0.700 0.700 1.000"/>
  </material>
  <material name="2dof_joint">
    <color rgba="0.500 0.500 0.500 1.000"/>
  </material>
  <material name="proximal">
    <color rgba="0.600 1.000 1.000 1.000"/>
  </material>
  <material name="middle">
    <color rgba="0.600 1.000 0.700 1.000"/>
  </material>
  <material name="distal">
    <color rgba="0.900 1.000 0.600 1.000"/>
  </material>  

  <!-- Adapt Hand links and joints-->  
  <link name="base_link">
    <inertial>
      <origin rpy="0 0 0" xyz="-0.00282625535112708 0.003041510004551977 -0.0554326706561243"/>
      <mass value="0.3570307896541811"/>
      <inertia ixx="0.001" ixy="0.0" ixz="-0.0" iyy="0.001" iyz="0.0" izz="0.001"/>
    </inertial>
    <visual>
      <origin rpy="0 0 0" xyz="0 0 0"/>
      <geometry>
        <mesh filename="/home/vigno/github/VMRobotControl.jl/URDFs/franka_hand_description/adapt_hand_assets/base_link.stl" scale="0.001 0.001 0.001"/>
      </geometry>
      <material name="hand_base"/>
    </visual>
    <collision>
      <origin rpy="0 0 0" xyz="0 0 0"/>
      <geometry>
        <mesh filename="/home/vigno/github/VMRobotControl.jl/URDFs/franka_hand_description/adapt_hand_assets/base_link.stl" scale="0.001 0.001 0.001"/>
      </geometry>
    </collision>
  </link>
  <link name="Pinky_Base_1">
    <inertial>
      <origin rpy="0 0 0" xyz="-0.003719233792189622 -0.0057457041933585695 0.0033210310886915492"/>
      <mass value="0.008894398346319696"/>
      <inertia ixx="0.001" ixy="0.0" ixz="-0.0" iyy="0.001" iyz="0.0" izz="0.001"/>
    </inertial>
    <visual>
      <origin rpy="0 0 0" xyz="-0.044117 -0.042555 -0.047304"/>
      <geometry>
        <mesh filename="/home/vigno/github/VMRobotControl.jl/URDFs/franka_hand_description/adapt_hand_assets/Pinky_Base_1.stl" scale="0.001 0.001 0.001"/>
      </geometry>
      <material name="finger_base"/>
    </visual>
    <collision>
      <origin rpy="0 0 0" xyz="-0.044117 -0.042555 -0.047304"/>
      <geometry>
        <mesh filename="/home/vigno/github/VMRobotControl.jl/URDFs/franka_hand_description/adapt_hand_assets/Pinky_Base_1.stl" scale="0.001 0.001 0.001"/>
      </geometry>
    </collision>
  </link>
  <link name="Thumb_base_1">
    <inertial>
      <origin rpy="0 0 0" xyz="-0.005945311775073393 0.0034765848028099067 -0.011375480481497623"/>
      <mass value="0.02220331765118904"/>
      <inertia ixx="0.001" ixy="0.0" ixz="-0.0" iyy="0.001" iyz="0.0" izz="0.001"/>
    </inertial>
    <visual>
      <origin rpy="0 0 0" xyz="0.018952 -0.014369 -0.028217"/>
      <geometry>
        <mesh filename="/home/vigno/github/VMRobotControl.jl/URDFs/franka_hand_description/adapt_hand_assets/Thumb_base_1.stl" scale="0.001 0.001 0.001"/>
      </geometry>
      <material name="finger_base"/>
    </visual>
    <collision>
      <origin rpy="0 0 0" xyz="0.018952 -0.014369 -0.028217"/>
      <geometry>
        <mesh filename="/home/vigno/github/VMRobotControl.jl/URDFs/franka_hand_description/adapt_hand_assets/Thumb_base_1.stl" scale="0.001 0.001 0.001"/>
      </geometry>
    </collision>
  </link>
  <link name="Thumb_2dof_joint_1">
    <inertial>
      <origin rpy="0 0 0" xyz="-0.0027227369487301326 -0.0041302767137553036 -0.006578727334875351"/>
      <mass value="0.04353433420750444"/>
      <inertia ixx="0.001" ixy="0.0" ixz="-0.0" iyy="0.001" iyz="0.0" izz="0.001"/>
    </inertial>
    <visual>
      <origin rpy="0 0 0" xyz="0.033209 -0.025198 -0.02075"/>
      <geometry>
        <mesh filename="/home/vigno/github/VMRobotControl.jl/URDFs/franka_hand_description/adapt_hand_assets/Thumb_2dof_joint_1.stl" scale="0.001 0.001 0.001"/>
      </geometry>
      <material name="2dof_joint"/>
    </visual>
    <collision>
      <origin rpy="0 0 0" xyz="0.033209 -0.025198 -0.02075"/>
      <geometry>
        <mesh filename="/home/vigno/github/VMRobotControl.jl/URDFs/franka_hand_description/adapt_hand_assets/Thumb_2dof_joint_1.stl" scale="0.001 0.001 0.001"/>
      </geometry>
    </collision>
  </link>
  <link name="Thumb_Proximal_1">
    <inertial>
      <origin rpy="0 0 0" xyz="-0.021005373038560662 -0.00018656491675926243 -0.0038864805339254276"/>
      <mass value="0.043341763821444314"/>
      <inertia ixx="0.001" ixy="0.0" ixz="-0.0" iyy="0.001" iyz="0.0" izz="0.001"/>
    </inertial>
    <visual>
      <origin rpy="0 0 0" xyz="0.04184 -0.027138 -0.011943"/>
      <geometry>
        <mesh filename="/home/vigno/github/VMRobotControl.jl/URDFs/franka_hand_description/adapt_hand_assets/Thumb_Proximal_1.stl" scale="0.001 0.001 0.001"/>
      </geometry>
      <material name="proximal"/>
    </visual>
    <collision>
      <origin rpy="0 0 0" xyz="0.04184 -0.027138 -0.011943"/>
      <geometry>
        <mesh filename="/home/vigno/github/VMRobotControl.jl/URDFs/franka_hand_description/adapt_hand_assets/Thumb_Proximal_1.stl" scale="0.001 0.001 0.001"/>
      </geometry>
    </collision>
  </link>
  <link name="Thumb_Middle_1">
    <inertial>
      <origin rpy="0 0 0" xyz="-0.015668648834712293 0.0007948645998734766 -0.0034563305955614505"/>
      <mass value="0.027065453694440095"/>
      <inertia ixx="0.001" ixy="0.0" ixz="-0.0" iyy="0.001" iyz="0.0" izz="0.001"/>
    </inertial>
    <visual>
      <origin rpy="0 0 0" xyz="0.08596 -0.026181 -0.003083"/>
      <geometry>
        <mesh filename="/home/vigno/github/VMRobotControl.jl/URDFs/franka_hand_description/adapt_hand_assets/Thumb_Middle_1.stl" scale="0.001 0.001 0.001"/>
      </geometry>
      <material name="middle"/>
    </visual>
    <collision>
      <origin rpy="0 0 0" xyz="0.08596 -0.026181 -0.003083"/>
      <geometry>
        <mesh filename="/home/vigno/github/VMRobotControl.jl/URDFs/franka_hand_description/adapt_hand_assets/Thumb_Middle_1.stl" scale="0.001 0.001 0.001"/>
      </geometry>
    </collision>
  </link>
  <link name="Thumb_Distal_1">
    <inertial>
      <origin rpy="0 0 0" xyz="-0.013086100877903545 0.0005521681407470135 -0.0016232707547861563"/>
      <mass value="0.021617344825550864"/>
      <inertia ixx="0.001" ixy="0.0" ixz="-0.0" iyy="0.001" iyz="0.0" izz="0.001"/>
    </inertial>
    <visual>
      <origin rpy="0 0 0" xyz="0.117424 -0.025127 0.002649"/>
      <geometry>
        <mesh filename="/home/vigno/github/VMRobotControl.jl/URDFs/franka_hand_description/adapt_hand_assets/Thumb_Distal_1.stl" scale="0.001 0.001 0.001"/>
      </geometry>
      <material name="distal"/>
    </visual>
    <collision>
      <origin rpy="0 0 0" xyz="0.117424 -0.025127 0.002649"/>
      <geometry>
        <mesh filename="/home/vigno/github/VMRobotControl.jl/URDFs/franka_hand_description/adapt_hand_assets/Thumb_Distal_1.stl" scale="0.001 0.001 0.001"/>
      </geometry>
    </collision>
  </link>
  <link name="Pinky_2dof_joint_1">
    <inertial>
      <origin rpy="0 0 0" xyz="0.0009655320392698355 -0.0024991679126516175 0.003883053257784902"/>
      <mass value="0.0074922865960129585"/>
      <inertia ixx="0.001" ixy="0.0" ixz="-0.0" iyy="0.001" iyz="0.0" izz="0.001"/>
    </inertial>
    <visual>
      <origin rpy="0 0 0" xyz="-0.043044 -0.042402 -0.055815"/>
      <geometry>
        <mesh filename="/home/vigno/github/VMRobotControl.jl/URDFs/franka_hand_description/adapt_hand_assets/Pinky_2dof_joint_1.stl" scale="0.001 0.001 0.001"/>
      </geometry>
      <material name="2dof_joint"/>
    </visual>
    <collision>
      <origin rpy="0 0 0" xyz="-0.043044 -0.042402 -0.055815"/>
      <geometry>
        <mesh filename="/home/vigno/github/VMRobotControl.jl/URDFs/franka_hand_description/adapt_hand_assets/Pinky_2dof_joint_1.stl" scale="0.001 0.001 0.001"/>
      </geometry>
    </collision>
  </link>
  <link name="Pinky_Proximal_1">
    <inertial>
      <origin rpy="0 0 0" xyz="0.007928224817666543 0.006170807631587338 0.012536508605590788"/>
      <mass value="0.027065453694440127"/>
      <inertia ixx="0.001" ixy="0.0" ixz="-0.0" iyy="0.001" iyz="0.0" izz="0.001"/>
    </inertial>
    <visual>
      <origin rpy="0 0 0" xyz="-0.047975 -0.041899 -0.064103"/>
      <geometry>
        <mesh filename="/home/vigno/github/VMRobotControl.jl/URDFs/franka_hand_description/adapt_hand_assets/Pinky_Proximal_1.stl" scale="0.001 0.001 0.001"/>
      </geometry>
      <material name="proximal"/>
    </visual>
    <collision>
      <origin rpy="0 0 0" xyz="-0.047975 -0.041899 -0.064103"/>
      <geometry>
        <mesh filename="/home/vigno/github/VMRobotControl.jl/URDFs/franka_hand_description/adapt_hand_assets/Pinky_Proximal_1.stl" scale="0.001 0.001 0.001"/>
      </geometry>
    </collision>
  </link>
  <link name="Pinky_Middle_1">
    <inertial>
      <origin rpy="0 0 0" xyz="0.0030496480518817787 0.003754077644590695 0.008944928959581933"/>
      <mass value="0.013713333273135108"/>
      <inertia ixx="0.001" ixy="0.0" ixz="-0.0" iyy="0.001" iyz="0.0" izz="0.001"/>
    </inertial>
    <visual>
      <origin rpy="0 0 0" xyz="-0.06287 -0.051905 -0.090599"/>
      <geometry>
        <mesh filename="/home/vigno/github/VMRobotControl.jl/URDFs/franka_hand_description/adapt_hand_assets/Pinky_Middle_1.stl" scale="0.001 0.001 0.001"/>
      </geometry>
      <material name="middle"/>
    </visual>
    <collision>
      <origin rpy="0 0 0" xyz="-0.06287 -0.051905 -0.090599"/>
      <geometry>
        <mesh filename="/home/vigno/github/VMRobotControl.jl/URDFs/franka_hand_description/adapt_hand_assets/Pinky_Middle_1.stl" scale="0.001 0.001 0.001"/>
      </geometry>
    </collision>
  </link>
  <link name="Pinky_Distal_1">
    <inertial>
      <origin rpy="0 0 0" xyz="0.005298840390167592 0.004233379169998802 0.008100187556237079"/>
      <mass value="0.016053961316673797"/>
      <inertia ixx="0.001" ixy="0.0" ixz="-0.0" iyy="0.001" iyz="0.0" izz="0.001"/>
    </inertial>
    <visual>
      <origin rpy="0 0 0" xyz="-0.072179 -0.058159 -0.107158"/>
      <geometry>
        <mesh filename="/home/vigno/github/VMRobotControl.jl/URDFs/franka_hand_description/adapt_hand_assets/Pinky_Distal_1.stl" scale="0.001 0.001 0.001"/>
      </geometry>
      <material name="distal"/>
    </visual>
    <collision>
      <origin rpy="0 0 0" xyz="-0.072179 -0.058159 -0.107158"/>
      <geometry>
        <mesh filename="/home/vigno/github/VMRobotControl.jl/URDFs/franka_hand_description/adapt_hand_assets/Pinky_Distal_1.stl" scale="0.001 0.001 0.001"/>
      </geometry>
    </collision>
  </link>
  <link name="Middle_Base_1">
    <inertial>
      <origin rpy="0 0 0" xyz="-0.0054752523709118775 -0.00511017974007371 0.0013360143460869334"/>
      <mass value="0.008894398346319696"/>
      <inertia ixx="0.001" ixy="0.0" ixz="-0.0" iyy="0.001" iyz="0.0" izz="0.001"/>
    </inertial>
    <visual>
      <origin rpy="0 0 0" xyz="-0.003904 -0.042167 -0.064419"/>
      <geometry>
        <mesh filename="/home/vigno/github/VMRobotControl.jl/URDFs/franka_hand_description/adapt_hand_assets/Middle_Base_1.stl" scale="0.001 0.001 0.001"/>
      </geometry>
      <material name="finger_base"/>
    </visual>
    <collision>
      <origin rpy="0 0 0" xyz="-0.003904 -0.042167 -0.064419"/>
      <geometry>
        <mesh filename="/home/vigno/github/VMRobotControl.jl/URDFs/franka_hand_description/adapt_hand_assets/Middle_Base_1.stl" scale="0.001 0.001 0.001"/>
      </geometry>
    </collision>
  </link>
  <link name="Middle_2dof_joint_1">
    <inertial>
      <origin rpy="0 0 0" xyz="-0.0012928812361565367 -0.002209895290024702 0.0039625085358881845"/>
      <mass value="0.0074922865960129585"/>
      <inertia ixx="0.001" ixy="0.0" ixz="-0.0" iyy="0.001" iyz="0.0" izz="0.001"/>
    </inertial>
    <visual>
      <origin rpy="0 0 0" xyz="0.001107 -0.042864 -0.071348"/>
      <geometry>
        <mesh filename="/home/vigno/github/VMRobotControl.jl/URDFs/franka_hand_description/adapt_hand_assets/Middle_2dof_joint_1.stl" scale="0.001 0.001 0.001"/>
      </geometry>
      <material name="2dof_joint"/>
    </visual>
    <collision>
      <origin rpy="0 0 0" xyz="0.001107 -0.042864 -0.071348"/>
      <geometry>
        <mesh filename="/home/vigno/github/VMRobotControl.jl/URDFs/franka_hand_description/adapt_hand_assets/Middle_2dof_joint_1.stl" scale="0.001 0.001 0.001"/>
      </geometry>
    </collision>
  </link>
  <link name="Middle_Proximal_1">
    <inertial>
      <origin rpy="0 0 0" xyz="0.001640526577038641 0.009026757175084693 0.020594526009798123"/>
      <mass value="0.04153025081752053"/>
      <inertia ixx="0.001" ixy="0.0" ixz="-0.0" iyy="0.001" iyz="0.0" izz="0.001"/>
    </inertial>
    <visual>
      <origin rpy="0 0 0" xyz="0.000818 -0.042715 -0.080999"/>
      <geometry>
        <mesh filename="/home/vigno/github/VMRobotControl.jl/URDFs/franka_hand_description/adapt_hand_assets/Middle_Proximal_1.stl" scale="0.001 0.001 0.001"/>
      </geometry>
      <material name="proximal"/>
    </visual>
    <collision>
      <origin rpy="0 0 0" xyz="0.000818 -0.042715 -0.080999"/>
      <geometry>
        <mesh filename="/home/vigno/github/VMRobotControl.jl/URDFs/franka_hand_description/adapt_hand_assets/Middle_Proximal_1.stl" scale="0.001 0.001 0.001"/>
      </geometry>
    </collision>
  </link>
  <link name="Middle_Middle_1">
    <inertial>
      <origin rpy="0 0 0" xyz="-0.00018916464072228222 0.006325216668670787 0.013678291230183964"/>
      <mass value="0.024840100290889285"/>
      <inertia ixx="0.001" ixy="0.0" ixz="-0.0" iyy="0.001" iyz="0.0" izz="0.001"/>
    </inertial>
    <visual>
      <origin rpy="0 0 0" xyz="-0.001263 -0.058358 -0.123142"/>
      <geometry>
        <mesh filename="/home/vigno/github/VMRobotControl.jl/URDFs/franka_hand_description/adapt_hand_assets/Middle_Middle_1.stl" scale="0.001 0.001 0.001"/>
      </geometry>
      <material name="middle"/>
    </visual>
    <collision>
      <origin rpy="0 0 0" xyz="-0.001263 -0.058358 -0.123142"/>
      <geometry>
        <mesh filename="/home/vigno/github/VMRobotControl.jl/URDFs/franka_hand_description/adapt_hand_assets/Middle_Middle_1.stl" scale="0.001 0.001 0.001"/>
      </geometry>
    </collision>
  </link>
  <link name="Middle_Distal_1">
    <inertial>
      <origin rpy="0 0 0" xyz="0.00123485740257297 0.0045066426093437195 0.00947432625420594"/>
      <mass value="0.01605396131667379"/>
      <inertia ixx="0.001" ixy="0.0" ixz="-0.0" iyy="0.001" iyz="0.0" izz="0.001"/>
    </inertial>
    <visual>
      <origin rpy="0 0 0" xyz="-0.00265 -0.068786 -0.151237"/>
      <geometry>
        <mesh filename="/home/vigno/github/VMRobotControl.jl/URDFs/franka_hand_description/adapt_hand_assets/Middle_Distal_1.stl" scale="0.001 0.001 0.001"/>
      </geometry>
      <material name="distal"/>
    </visual>
    <collision>
      <origin rpy="0 0 0" xyz="-0.00265 -0.068786 -0.151237"/>
      <geometry>
        <mesh filename="/home/vigno/github/VMRobotControl.jl/URDFs/franka_hand_description/adapt_hand_assets/Middle_Distal_1.stl" scale="0.001 0.001 0.001"/>
      </geometry>
    </collision>
  </link>
  <link name="Index_Base_1">
    <inertial>
      <origin rpy="0 0 0" xyz="-0.005814202252379122 -0.004905225233519626 1.4665495806198692e-05"/>
      <mass value="0.008894398346319696"/>
      <inertia ixx="0.001" ixy="0.0" ixz="-0.0" iyy="0.001" iyz="0.0" izz="0.001"/>
    </inertial>
    <visual>
      <origin rpy="0 0 0" xyz="0.01948 -0.043857 -0.065103"/>
      <geometry>
        <mesh filename="/home/vigno/github/VMRobotControl.jl/URDFs/franka_hand_description/adapt_hand_assets/Index_Base_1.stl" scale="0.001 0.001 0.001"/>
      </geometry>
      <material name="finger_base"/>
    </visual>
    <collision>
      <origin rpy="0 0 0" xyz="0.01948 -0.043857 -0.065103"/>
      <geometry>
        <mesh filename="/home/vigno/github/VMRobotControl.jl/URDFs/franka_hand_description/adapt_hand_assets/Index_Base_1.stl" scale="0.001 0.001 0.001"/>
      </geometry>
    </collision>
  </link>
  <link name="Index_2dof_joint_1">
    <inertial>
      <origin rpy="0 0 0" xyz="-0.0021496805311756496 -0.0022654497982250305 0.0035353824354107805"/>
      <mass value="0.0074922865960129585"/>
      <inertia ixx="0.001" ixy="0.0" ixz="-0.0" iyy="0.001" iyz="0.0" izz="0.001"/>
    </inertial>
    <visual>
      <origin rpy="0 0 0" xyz="0.025764 -0.044569 -0.070901"/>
      <geometry>
        <mesh filename="/home/vigno/github/VMRobotControl.jl/URDFs/franka_hand_description/adapt_hand_assets/Index_2dof_joint_1.stl" scale="0.001 0.001 0.001"/>
      </geometry>
      <material name="2dof_joint"/>
    </visual>
    <collision>
      <origin rpy="0 0 0" xyz="0.025764 -0.044569 -0.070901"/>
      <geometry>
        <mesh filename="/home/vigno/github/VMRobotControl.jl/URDFs/franka_hand_description/adapt_hand_assets/Index_2dof_joint_1.stl" scale="0.001 0.001 0.001"/>
      </geometry>
    </collision>
  </link>
  <link name="Index_Proximal_1">
    <inertial>
      <origin rpy="0 0 0" xyz="-0.0018373004935238642 0.007506135501600397 0.01850154867200461"/>
      <mass value="0.03596686730864345"/>
      <inertia ixx="0.001" ixy="0.0" ixz="-0.0" iyy="0.001" iyz="0.0" izz="0.001"/>
    </inertial>
    <visual>
      <origin rpy="0 0 0" xyz="0.027446 -0.044129 -0.0804"/>
      <geometry>
        <mesh filename="/home/vigno/github/VMRobotControl.jl/URDFs/franka_hand_description/adapt_hand_assets/Index_Proximal_1.stl" scale="0.001 0.001 0.001"/>
      </geometry>
      <material name="proximal"/>
    </visual>
    <collision>
      <origin rpy="0 0 0" xyz="0.027446 -0.044129 -0.0804"/>
      <geometry>
        <mesh filename="/home/vigno/github/VMRobotControl.jl/URDFs/franka_hand_description/adapt_hand_assets/Index_Proximal_1.stl" scale="0.001 0.001 0.001"/>
      </geometry>
    </collision>
  </link>
  <link name="Index_Middle_1">
    <inertial>
      <origin rpy="0 0 0" xyz="-0.0027314570239129823 0.005930191023642534 0.01358428054010058"/>
      <mass value="0.024840100290889327"/>
      <inertia ixx="0.001" ixy="0.0" ixz="-0.0" iyy="0.001" iyz="0.0" izz="0.001"/>
    </inertial>
    <visual>
      <origin rpy="0 0 0" xyz="0.032733 -0.056851 -0.117952"/>
      <geometry>
        <mesh filename="/home/vigno/github/VMRobotControl.jl/URDFs/franka_hand_description/adapt_hand_assets/Index_Middle_1.stl" scale="0.001 0.001 0.001"/>
      </geometry>
      <material name="middle"/>
    </visual>
    <collision>
      <origin rpy="0 0 0" xyz="0.032733 -0.056851 -0.117952"/>
      <geometry>
        <mesh filename="/home/vigno/github/VMRobotControl.jl/URDFs/franka_hand_description/adapt_hand_assets/Index_Middle_1.stl" scale="0.001 0.001 0.001"/>
      </geometry>
    </collision>
  </link>
  <link name="Index_Distal_1">
    <inertial>
      <origin rpy="0 0 0" xyz="-0.0005509005628277913 0.004173844490997988 0.009689631704284385"/>
      <mass value="0.01605396131667379"/>
      <inertia ixx="0.001" ixy="0.0" ixz="-0.0" iyy="0.001" iyz="0.0" izz="0.001"/>
    </inertial>
    <visual>
      <origin rpy="0 0 0" xyz="0.036699 -0.066393 -0.146116"/>
      <geometry>
        <mesh filename="/home/vigno/github/VMRobotControl.jl/URDFs/franka_hand_description/adapt_hand_assets/Index_Distal_1.stl" scale="0.001 0.001 0.001"/>
      </geometry>
      <material name="distal"/>
    </visual>
    <collision>
      <origin rpy="0 0 0" xyz="0.036699 -0.066393 -0.146116"/>
      <geometry>
        <mesh filename="/home/vigno/github/VMRobotControl.jl/URDFs/franka_hand_description/adapt_hand_assets/Index_Distal_1.stl" scale="0.001 0.001 0.001"/>
      </geometry>
    </collision>
  </link>
  <link name="Ring_Base_1">
    <inertial>
      <origin rpy="0 0 0" xyz="0.005169923665215768 -0.0055778869574305695 -0.00018480774047401755"/>
      <mass value="0.008894398346319696"/>
      <inertia ixx="0.001" ixy="0.0" ixz="-0.0" iyy="0.001" iyz="0.0" izz="0.001"/>
    </inertial>
    <visual>
      <origin rpy="0 0 0" xyz="-0.014948 -0.042388 -0.062559"/>
      <geometry>
        <mesh filename="/home/vigno/github/VMRobotControl.jl/URDFs/franka_hand_description/adapt_hand_assets/Ring_Base_1.stl" scale="0.001 0.001 0.001"/>
      </geometry>
      <material name="finger_base"/>
    </visual>
    <collision>
      <origin rpy="0 0 0" xyz="-0.014948 -0.042388 -0.062559"/>
      <geometry>
        <mesh filename="/home/vigno/github/VMRobotControl.jl/URDFs/franka_hand_description/adapt_hand_assets/Ring_Base_1.stl" scale="0.001 0.001 0.001"/>
      </geometry>
    </collision>
  </link>
  <link name="Ring_2dof_joint_1">
    <inertial>
      <origin rpy="0 0 0" xyz="-0.00032209566130320805 -0.0022285906080109705 0.004144757505959121"/>
      <mass value="0.0074922865960129585"/>
      <inertia ixx="0.001" ixy="0.0" ixz="-0.0" iyy="0.001" iyz="0.0" izz="0.001"/>
    </inertial>
    <visual>
      <origin rpy="0 0 0" xyz="-0.021789 -0.042616 -0.067733"/>
      <geometry>
        <mesh filename="/home/vigno/github/VMRobotControl.jl/URDFs/franka_hand_description/adapt_hand_assets/Ring_2dof_joint_1.stl" scale="0.001 0.001 0.001"/>
      </geometry>
      <material name="2dof_joint"/>
    </visual>
    <collision>
      <origin rpy="0 0 0" xyz="-0.021789 -0.042616 -0.067733"/>
      <geometry>
        <mesh filename="/home/vigno/github/VMRobotControl.jl/URDFs/franka_hand_description/adapt_hand_assets/Ring_2dof_joint_1.stl" scale="0.001 0.001 0.001"/>
      </geometry>
    </collision>
  </link>
  <link name="Ring_Proximal_1">
    <inertial>
      <origin rpy="0 0 0" xyz="0.005671866291842076 0.008114842391722644 0.01743578994741593"/>
      <mass value="0.03596686730864345"/>
      <inertia ixx="0.001" ixy="0.0" ixz="-0.0" iyy="0.001" iyz="0.0" izz="0.001"/>
    </inertial>
    <visual>
      <origin rpy="0 0 0" xyz="-0.02429 -0.042461 -0.077059"/>
      <geometry>
        <mesh filename="/home/vigno/github/VMRobotControl.jl/URDFs/franka_hand_description/adapt_hand_assets/Ring_Proximal_1.stl" scale="0.001 0.001 0.001"/>
      </geometry>
      <material name="proximal"/>
    </visual>
    <collision>
      <origin rpy="0 0 0" xyz="-0.02429 -0.042461 -0.077059"/>
      <geometry>
        <mesh filename="/home/vigno/github/VMRobotControl.jl/URDFs/franka_hand_description/adapt_hand_assets/Ring_Proximal_1.stl" scale="0.001 0.001 0.001"/>
      </geometry>
    </collision>
  </link>
  <link name="Ring_Middle_1">
    <inertial>
      <origin rpy="0 0 0" xyz="0.002888268604018758 0.006309223956108466 0.013378812291919479"/>
      <mass value="0.024840100290889327"/>
      <inertia ixx="0.001" ixy="0.0" ixz="-0.0" iyy="0.001" iyz="0.0" izz="0.001"/>
    </inertial>
    <visual>
      <origin rpy="0 0 0" xyz="-0.034542 -0.056348 -0.113143"/>
      <geometry>
        <mesh filename="/home/vigno/github/VMRobotControl.jl/URDFs/franka_hand_description/adapt_hand_assets/Ring_Middle_1.stl" scale="0.001 0.001 0.001"/>
      </geometry>
      <material name="middle"/>
    </visual>
    <collision>
      <origin rpy="0 0 0" xyz="-0.034542 -0.056348 -0.113143"/>
      <geometry>
        <mesh filename="/home/vigno/github/VMRobotControl.jl/URDFs/franka_hand_description/adapt_hand_assets/Ring_Middle_1.stl" scale="0.001 0.001 0.001"/>
      </geometry>
    </collision>
  </link>
  <link name="Ring_Distal_1">
    <inertial>
      <origin rpy="0 0 0" xyz="0.003328160524667584 0.0045120745366107745 0.008954378017708264"/>
      <mass value="0.01605396131667379"/>
      <inertia ixx="0.001" ixy="0.0" ixz="-0.0" iyy="0.001" iyz="0.0" izz="0.001"/>
    </inertial>
    <visual>
      <origin rpy="0 0 0" xyz="-0.042231 -0.066763 -0.140205"/>
      <geometry>
        <mesh filename="/home/vigno/github/VMRobotControl.jl/URDFs/franka_hand_description/adapt_hand_assets/Ring_Distal_1.stl" scale="0.001 0.001 0.001"/>
      </geometry>
      <material name="distal"/>
    </visual>
    <collision>
      <origin rpy="0 0 0" xyz="-0.042231 -0.066763 -0.140205"/>
      <geometry>
        <mesh filename="/home/vigno/github/VMRobotControl.jl/URDFs/franka_hand_description/adapt_hand_assets/Ring_Distal_1.stl" scale="0.001 0.001 0.001"/>
      </geometry>
    </collision>
  </link>
  <link name="Palm_1">
    <inertial>
      <origin rpy="0 0 0" xyz="0.01930283090203591 0.016231507625652328 0.04923347887171639"/>
      <mass value="0.3850187975331173"/>
      <inertia ixx="0.001" ixy="0.0" ixz="-0.0" iyy="0.001" iyz="0.0" izz="0.001"/>
    </inertial>
    <visual>
      <origin rpy="0 0 0" xyz="0.017826 -0.003021 0.027998"/>
      <geometry>
        <mesh filename="/home/vigno/github/VMRobotControl.jl/URDFs/franka_hand_description/adapt_hand_assets/Palm_1.stl" scale="0.001 0.001 0.001"/>
      </geometry>
      <material name="hand_base"/>
    </visual>
    <collision>
      <origin rpy="0 0 0" xyz="0.017826 -0.003021 0.027998"/>
      <geometry>
        <mesh filename="/home/vigno/github/VMRobotControl.jl/URDFs/franka_hand_description/adapt_hand_assets/Palm_1.stl" scale="0.001 0.001 0.001"/>
      </geometry>
    </collision>
  </link>
  <link name="Wrist_joint_1">
    <inertial>
      <origin rpy="0 0 0" xyz="-2.553852486201179e-07 -0.015000033851113629 -1.0745680277174374e-05"/>
      <mass value="0.06557007036604455"/>
      <inertia ixx="0.001" ixy="0.0" ixz="-0.0" iyy="0.001" iyz="0.0" izz="0.001"/>
    </inertial>
    <visual>
      <origin rpy="0 0 0" xyz="0.002826 -0.018021 0.027987"/>
      <geometry>
        <mesh filename="/home/vigno/github/VMRobotControl.jl/URDFs/franka_hand_description/adapt_hand_assets/Wrist_joint_1.stl" scale="0.001 0.001 0.001"/>
      </geometry>
      <material name="finger_base"/>
    </visual>
    <collision>
      <origin rpy="0 0 0" xyz="0.002826 -0.018021 0.027987"/>
      <geometry>
        <mesh filename="/home/vigno/github/VMRobotControl.jl/URDFs/franka_hand_description/adapt_hand_assets/Wrist_joint_1.stl" scale="0.001 0.001 0.001"/>
      </geometry>
    </collision>
  </link>
  <joint name="Pinky_Base" type="fixed">
    <origin rpy="0 0 0" xyz="0.061943 0.039534 0.075302"/>
    <parent link="Palm_1"/>
    <child link="Pinky_Base_1"/>
  </joint>
  <joint name="Thumb_Base" type="fixed">
    <origin rpy="0 0 0" xyz="-0.001126 0.011348 0.056215"/>
    <parent link="Palm_1"/>
    <child link="Thumb_base_1"/>
  </joint>
  <joint name="Thumb_CMC1" type="revolute">
    <origin rpy="0 0 0" xyz="-0.014257 0.010829 -0.007467"/>
    <parent link="Thumb_base_1"/>
    <child link="Thumb_2dof_joint_1"/>
    <axis xyz="0.182125 -0.177737 -0.967078"/>
    <limit effort="100" lower="0.0" upper="2.007129" velocity="100"/>
  </joint>
  <joint name="Thumb_CMC2" type="revolute">
    <origin rpy="0 0 0" xyz="-0.008631 0.00194 -0.008807"/>
    <parent link="Thumb_2dof_joint_1"/>
    <child link="Thumb_Proximal_1"/>
    <axis xyz="-0.0 -0.983527 0.180761"/>
    <limit effort="100" lower="-1.570796" upper="0.0" velocity="100"/>
  </joint>
  <joint name="Thumb_MCP" type="revolute">
    <origin rpy="0 0 0" xyz="-0.04412 -0.000957 -0.00886"/>
    <parent link="Thumb_Proximal_1"/>
    <child link="Thumb_Middle_1"/>
    <axis xyz="-0.168863 -0.20364 0.964373"/>
    <limit effort="100" lower="-2.007129" upper="0.0" velocity="100"/>
  </joint>
  <joint name="Thumb_IP" type="revolute">
    <origin rpy="0 0 0" xyz="-0.031464 -0.001054 -0.005732"/>
    <parent link="Thumb_Middle_1"/>
    <child link="Thumb_Distal_1"/>
    <axis xyz="-0.168863 -0.20364 0.964373"/>
    <limit effort="100" lower="-1.396263" upper="0.0" velocity="100"/>
    <mimic joint="Thumb_MCP" multiplier="1" offset="0"/>
  </joint>
  <joint name="Pinky_MCP_Spread" type="revolute">
    <origin rpy="0 0 0" xyz="-0.001073 -0.000153 0.008511"/>
    <parent link="Pinky_Base_1"/>
    <child link="Pinky_2dof_joint_1"/>
    <axis xyz="-0.211896 0.947676 -0.238768"/>
    <limit effort="100" lower="0.0" upper="0.174533" velocity="100"/>
  </joint>
  <joint name="Pinky_MCP" type="revolute">
    <origin rpy="0 0 0" xyz="0.004931 -0.000503 0.008288"/>
    <parent link="Pinky_2dof_joint_1"/>
    <child link="Pinky_Proximal_1"/>
    <axis xyz="0.859324 0.064308 -0.507372"/>
    <limit effort="100" lower="-1.570796" upper="0.0" velocity="100"/>
  </joint>
  <joint name="Pinky_PIP" type="revolute">
    <origin rpy="0 0 0" xyz="0.014895 0.010006 0.026496"/>
    <parent link="Pinky_Proximal_1"/>
    <child link="Pinky_Middle_1"/>
    <axis xyz="0.859324 0.064308 -0.507372"/>
    <limit effort="100" lower="-1.22173" upper="0.0" velocity="100"/>
  </joint>
  <joint name="Pinky_DIP" type="revolute">
    <origin rpy="0 0 0" xyz="0.009309 0.006254 0.016559"/>
    <parent link="Pinky_Middle_1"/>
    <child link="Pinky_Distal_1"/>
    <axis xyz="0.859324 0.064308 -0.507372"/>
    <limit effort="100" lower="-1.22173" upper="0.0" velocity="100"/>
    <mimic joint="Pinky_PIP" multiplier="1.0" offset="0.0"/>
  </joint>
  <joint name="Middle_Base" type="fixed">
    <origin rpy="0 0 0" xyz="0.02173 0.039146 0.092417"/>
    <parent link="Palm_1"/>
    <child link="Middle_Base_1"/>
  </joint>
  <joint name="Middle_MCP_Spread" type="revolute">
    <origin rpy="0 0 0" xyz="-0.005011 0.000697 0.006929"/>
    <parent link="Middle_Base_1"/>
    <child link="Middle_2dof_joint_1"/>
    <axis xyz="0.036359 0.936295 -0.349327"/>
    <limit effort="100" lower="0.0" upper="0.0" velocity="100"/>
    <mimic joint="Pinky_MCP_Spread" multiplier="-1.0" offset="0.0"/>
  </joint>
  <joint name="Middle_MCP" type="revolute">
    <origin rpy="0 0 0" xyz="0.000289 -0.000149 0.009651"/>
    <parent link="Middle_2dof_joint_1"/>
    <child link="Middle_Proximal_1"/>
    <axis xyz="0.998268 -0.050205 -0.030661"/>
    <limit effort="100" lower="-1.570796" upper="0.0" velocity="100"/>
  </joint>
  <joint name="Middle_PIP" type="revolute">
    <origin rpy="0 0 0" xyz="0.002081 0.015643 0.042143"/>
    <parent link="Middle_Proximal_1"/>
    <child link="Middle_Middle_1"/>
    <axis xyz="0.998268 -0.050205 -0.030661"/>
    <limit effort="100" lower="-1.22173" upper="0.0" velocity="100"/>
  </joint>
  <joint name="Middle_DIP" type="revolute">
    <origin rpy="0 0 0" xyz="0.001387 0.010428 0.028095"/>
    <parent link="Middle_Middle_1"/>
    <child link="Middle_Distal_1"/>
    <axis xyz="0.998268 -0.050205 -0.030661"/>
    <limit effort="100" lower="-1.22173" upper="0.0" velocity="100"/>
    <mimic joint="Middle_PIP" multiplier="1.0" offset="0.0"/>
  </joint>
  <joint name="Index_Base" type="fixed">
    <origin rpy="0 0 0" xyz="-0.001654 0.040836 0.093101"/>
    <parent link="Palm_1"/>
    <child link="Index_Base_1"/>
  </joint>
  <joint name="Index_MCP_Spread" type="revolute">
    <origin rpy="0 0 0" xyz="-0.006284 0.000712 0.005798"/>
    <parent link="Index_Base_1"/>
    <child link="Index_2dof_joint_1"/>
    <axis xyz="0.140517 0.943569 -0.299886"/>
    <limit effort="100" lower="-0.174533" upper="0.0" velocity="100"/>
    <mimic joint="Pinky_MCP_Spread" multiplier="-1.0" offset="0.0"/>
  </joint>
  <joint name="Index_MCP" type="revolute">
    <origin rpy="0 0 0" xyz="-0.001682 -0.00044 0.009499"/>
    <parent link="Index_2dof_joint_1"/>
    <child link="Index_Proximal_1"/>
    <axis xyz="0.981214 -0.092278 0.169421"/>
    <limit effort="100" lower="-1.570796" upper="0.0" velocity="100"/>
  </joint>
  <joint name="Index_PIP" type="revolute">
    <origin rpy="0 0 0" xyz="-0.005287 0.012722 0.037552"/>
    <parent link="Index_Proximal_1"/>
    <child link="Index_Middle_1"/>
    <axis xyz="0.981214 -0.092278 0.169421"/>
    <limit effort="100" lower="-1.22173" upper="0.0" velocity="100"/>
  </joint>
  <joint name="Index_DIP" type="revolute">
    <origin rpy="0 0 0" xyz="-0.003966 0.009542 0.028164"/>
    <parent link="Index_Middle_1"/>
    <child link="Index_Distal_1"/>
    <axis xyz="0.981214 -0.092278 0.169421"/>
    <limit effort="100" lower="-1.22173" upper="0.0" velocity="100"/>
    <mimic joint="Index_PIP" multiplier="1.0" offset="0.0"/>
  </joint>
  <joint name="Ring_Base" type="fixed">
    <origin rpy="0 0 0" xyz="0.032774 0.039367 0.090557"/>
    <parent link="Palm_1"/>
    <child link="Ring_Base_1"/>
  </joint>
  <joint name="Ring_MCP_Spread" type="revolute">
    <origin rpy="0 0 0" xyz="0.006841 0.000228 0.005174"/>
    <parent link="Ring_Base_1"/>
    <child link="Ring_2dof_joint_1"/>
    <axis xyz="-0.055584 0.937022 -0.34482"/>
    <limit effort="100" lower="0.0" upper="0.174533" velocity="100"/>
    <mimic joint="Pinky_MCP_Spread" multiplier="1.0" offset="0.0"/>
  </joint>
  <joint name="Ring_MCP" type="revolute">
    <origin rpy="0 0 0" xyz="0.002501 -0.000155 0.009326"/>
    <parent link="Ring_2dof_joint_1"/>
    <child link="Ring_Proximal_1"/>
    <axis xyz="0.964998 -0.038236 -0.259457"/>
    <limit effort="100" lower="-1.570796" upper="0.0" velocity="100"/>
  </joint>
  <joint name="Ring_PIP" type="revolute">
    <origin rpy="0 0 0" xyz="0.010252 0.013887 0.036084"/>
    <parent link="Ring_Proximal_1"/>
    <child link="Ring_Middle_1"/>
    <axis xyz="0.964998 -0.038236 -0.259457"/>
    <limit effort="100" lower="-1.22173" upper="0.0" velocity="100"/>
  </joint>
  <joint name="Ring_DIP" type="revolute">
    <origin rpy="0 0 0" xyz="0.007689 0.010415 0.027062"/>
    <parent link="Ring_Middle_1"/>
    <child link="Ring_Distal_1"/>
    <axis xyz="0.964998 -0.038236 -0.259457"/>
    <limit effort="100" lower="-1.22173" upper="0.0" velocity="100"/>
    <mimic joint="Ring_PIP" multiplier="1.0" offset="0.0"/>
  </joint>
  <joint name="Wrist_Pitch" type="revolute">
    <origin rpy="0 0 0" xyz="-0.015 -0.015 -1.1e-05"/>
    <parent link="Wrist_joint_1"/>
    <child link="Palm_1"/>
    <axis xyz="-1.0 0.0 -0.0"/>
    <limit effort="100" lower="-0.01" upper="0.01" velocity="100"/>
  </joint>
  <joint name="Wrist_Yaw" type="revolute">
    <origin rpy="0 0 0" xyz="-0.002826 0.018021 -0.027987"/>
    <parent link="base_link"/>
    <child link="Wrist_joint_1"/>
    <axis xyz="0.0 1.0 0.000749"/>
    <limit effort="100" lower="-0.01" upper="0.01" velocity="100"/>
  </joint>
  
</robot>
